Workbook

Sheet PAGOS_ACTUALIZAR_2026
M1: T
A2: 15/12/2025 | B2: 2025003339 | C2: 953-2025 | D2: 4.730.000,00 | E2: 27105277 | F2: MARYBELL LUCIA BENITEZ ROSERO | G2: 873 | J2: 873 | K2: 4.730.000,00 | M2: =VLOOKUP(PAGOS_ACTUALIZAR_2026!B2,'CARGADOS 2025 DICIEMBRE CIERRE'!B2:B557,1,0) -> 2025003339
A3: 15/12/2025 | B3: 2025003340 | C3: 877-2025 | D3: 3.150.000,00 | E3: 1085265947 | F3: MARCELA JAZMIN TIMANA MAIGUAL | G3: 873 | J3: 873 | K3: 3.150.000,00 | M3: =VLOOKUP(PAGOS_ACTUALIZAR_2026!B3,'CARGADOS 2025 DICIEMBRE CIERRE'!B3:B558,1,0) -> 2025003340
A4: 15/12/2025 | B4: 2025003341 | C4: 982-2025 | D4: 3.150.000,00 | E4: 27222016 | F4: ALBA JULIA RODRIGUEZ MORA | G4: 873 | J4: 873 | K4: 3.150.000,00 | M4: =VLOOKUP(PAGOS_ACTUALIZAR_2026!B4,'CARGADOS 2025 DICIEMBRE CIERRE'!B4:B559,1,0) -> 2025003341
A5: 15/12/2025 | B5: 2025003342 | C5: 1034-2025 | D5: 2.000.000,00 | E5: 59313273 | F5: AURA INES CHACHINOY POTOSI | G5: 873 | J5: 873 | K5: 2.000.000,00 | M5: =VLOOKUP(PAGOS_ACTUALIZAR_2026!B5,'CARGADOS 2025 DICIEMBRE CIERRE'!B5:B560,1,0) -> 2025003342
A6: 15/12/2025 | B6: 2025003343 | C6: 1150-2025 | D6: 3.150.000,00 | E6: 1085331508 | F6: NESLY YANID MUÑOZ ORTÍZ | G6: 873 | J6: 873 | K6: 3.150.000,00 | M6: =VLOOKUP(PAGOS_ACTUALIZAR_2026!B6,'CARGADOS 2025 DICIEMBRE CIERRE'!B6:B561,1,0) -> 2025003343
A7: 15/12/2025 | B7: 2025003344 | C7: 827-2025 | D7: 3.150.000,00 | E7: 27088197 | F7: PAULA ANDREA MANOSALVA UNIGARRO | G7: 873 | J7: 873 | K7: 3.150.000,00 | M7: =VLOOKUP(PAGOS_ACTUALIZAR_2026!B7,'CARGADOS 2025 DICIEMBRE CIERRE'!B7:B562,1,0) -> 2025003344
A8: 15/12/2025 | B8: 2025003345 | C8: 951-2025 | D8: 6.300.000,00 | E8: 37085864 | F8: ANA VIVIANA BENAVIDES MORENO | G8: 873 | J8: 873 | K8: 6.300.000,00 | M8: =VLOOKUP(PAGOS_ACTUALIZAR_2026!B8,'CARGADOS 2025 DICIEMBRE CIERRE'!B8:B563,1,0) -> 2025003345
A9: 15/12/2025 | B9: 2025003346 | C9: 1112-2025 | D9: 6.300.000,00 | E9: 1085254153 | F9: LISETH ELIANA BENAVIDES ARCOS | G9: 873 | J9: 873 | K9: 6.300.000,00 | M9: =VLOOKUP(PAGOS_ACTUALIZAR_2026!B9,'CARGADOS 2025 DICIEMBRE CIERRE'!B9:B564,1,0) -> 2025003346
A10: 15/12/2025 | B10: 2025003347 | C10: 1165-2025 | D10: 3.150.000,00 | E10: 1233192104 | F10: DIEGO DAVID TORRES LUNA | G10: 873 | J10: 873 | K10: 3.150.000,00 | M10: =VLOOKUP(PAGOS_ACTUALIZAR_2026!B10,'CARGADOS 2025 DICIEMBRE CIERRE'!B10:B565,1,0) -> 2025003347
A11: 15/12/2025 | B11: 2025003348 | C11: 1140-2025 | D11: 7.800.000,00 | E11: 1085307962 | F11: DANIELA ALEJANDRA TOBAR GOMEZ | G11: 873 | J11: 873 | K11: 7.800.000,00 | M11: =VLOOKUP(PAGOS_ACTUALIZAR_2026!B11,'CARGADOS 2025 DICIEMBRE CIERRE'!B11:B566,1,0) -> 2025003348
A12: 15/12/2025 | B12: 2025003349 | C12: 860-2025 | D12: 4.730.000,00 | E12: 1005829176 | F12: ESTEFANIA CORREA GUERRERO | G12: 873 | J12: 873 | K12: 4.730.000,00 | M12: =VLOOKUP(PAGOS_ACTUALIZAR_2026!B12,'CARGADOS 2025 DICIEMBRE CIERRE'!B12:B567,1,0) -> 2025003349
A13: 15/12/2025 | B13: 2025003350 | C13: 1040-2025 | D13: 7.800.000,00 | E13: 87065647 | F13: JHON JAIME LOPEZ GUERRERO | G13: 873 | J13: 873 | K13: 7.800.000,00 | M13: =VLOOKUP(PAGOS_ACTUALIZAR_2026!B13,'CARGADOS 2025 DICIEMBRE CIERRE'!B13:B568,1,0) -> 2025003350
... A239: 19/12/2025 | B239: 2025003675 | C239: 1124-2025 | D239: 3.150.000,00 | E239: 59833899 | F239: ANDREA LILIANA LAGUNA RUALES | G239: 873 | J239: 873 | K239: 3.150.000,00 | M239: =VLOOKUP(PAGOS_ACTUALIZAR_2026!B239,'CARGADOS 2025 DICIEMBRE CIERRE'!B239:B794,1,0) -> 2025003675
A240: 19/12/2025 | B240: 2025003676 | C240: 8952025 | D240: 3.150.000,00 | E240: 27087122 | F240: MARITZA ROCIO OLIVA CUZ | G240: 873 | J240: 873 | K240: 3.150.000,00 | M240: =VLOOKUP(PAGOS_ACTUALIZAR_2026!B240,'CARGADOS 2025 DICIEMBRE CIERRE'!B240:B795,1,0) -> 2025003676
A241: 19/12/2025 | B241: 2025003677 | C241: 1104-2025 | D241: 2.000.000,00 | E241: 1085268450 | F241: MONICA PATRICIA JOJOA BOTINA | G241: 873 | J241: 873 | K241: 2.000.000,00 | M241: =VLOOKUP(PAGOS_ACTUALIZAR_2026!B241,'CARGADOS 2025 DICIEMBRE CIERRE'!B241:B796,1,0) -> 2025003677
A242: 19/12/2025 | B242: 2025003678 | C242: 1142-2025 | D242: 3.150.000,00 | E242: 1088799080 | F242: RUBY MARCELA AUCU PAREDES | G242: 873 | J242: 873 | K242: 3.150.000,00 | M242: =VLOOKUP(PAGOS_ACTUALIZAR_2026!B242,'CARGADOS 2025 DICIEMBRE CIERRE'!B242:B797,1,0) -> 2025003678
A243: 19/12/2025 | B243: 2025003679 | C243: 763-2025 | D243: 6.300.000,00 | E243: 1085277976 | F243: ADRIANA MARIA HIDALGO ENRIQUEZ | G243: 873 | J243: 873 | K243: 6.300.000,00 | M243: =VLOOKUP(PAGOS_ACTUALIZAR_2026!B243,'CARGADOS 2025 DICIEMBRE CIERRE'!B243:B798,1,0) -> 2025003679
A244: 19/12/2025 | B244: 2025003680 | C244: 1033-2025 | D244: 2.000.000,00 | E244: 1085313195 | F244: DIANA MILENA BOTINA JOSA | G244: 873 | J244: 873 | K244: 2.000.000,00 | M244: =VLOOKUP(PAGOS_ACTUALIZAR_2026!B244,'CARGADOS 2025 DICIEMBRE CIERRE'!B244:B799,1,0) -> 2025003680
A245: 19/12/2025 | B245: 2025003682 | C245: 1113-2025 | D245: 2.000.000,00 | E245: 37083933 | F245: LISSETH YAMILE HUERTAS TENGANAN | G245: 873 | J245: 873 | K245: 2.000.000,00 | M245: =VLOOKUP(PAGOS_ACTUALIZAR_2026!B245,'CARGADOS 2025 DICIEMBRE CIERRE'!B245:B800,1,0) -> 2025003682
A246: 19/12/2025 | B246: 2025003683 | C246: 1095-2025 | D246: 3.150.000,00 | E246: 98391531 | F246: HECTOR GERMAN OJEDA CERON | G246: 873 | J246: 873 | K246: 3.150.000,00 | M246: =VLOOKUP(PAGOS_ACTUALIZAR_2026!B246,'CARGADOS 2025 DICIEMBRE CIERRE'!B246:B801,1,0) -> 2025003683
A247: 19/12/2025 | B247: 2025003684 | C247: 1149-2025 | D247: 2.000.000,00 | E247: 1085312669 | F247: LILIANA DEL CARMEN VERGARA BOTINA | G247: 873 | J247: 873 | K247: 2.000.000,00 | M247: =VLOOKUP(PAGOS_ACTUALIZAR_2026!B247,'CARGADOS 2025 DICIEMBRE CIERRE'!B247:B802,1,0) -> 2025003684
A248: 19/12/2025 | B248: 2025003685 | C248: 781-2025 | D248: 6.300.000,00 | E248: 1010010954 | F248: JULIANA VALENTINA MENDEZ ORTÍZ | G248: 873 | J248: 873 | K248: 6.300.000,00 | M248: =VLOOKUP(PAGOS_ACTUALIZAR_2026!B248,'CARGADOS 2025 DICIEMBRE CIERRE'!B248:B803,1,0) -> 2025003685
A249: 19/12/2025 | B249: 2025003686 | C249: 1022-2025 | D249: 2.000.000,00 | E249: 1081282855 | F249: MARIA SOFIA CHAVEZ JOJOA | G249: 873 | J249: 873 | K249: 2.000.000,00 | M249: =VLOOKUP(PAGOS_ACTUALIZAR_2026!B249,'CARGADOS 2025 DICIEMBRE CIERRE'!B249:B804,1,0) -> 2025003686
A250: 19/12/2025 | B250: 2025003687 | C250: 903-2025 | D250: 3.150.000,00 | E250: 1081594639 | F250: ANYI NATALY FARINANGO CHAVEZ | G250: 873 | J250: 873 | K250: 3.150.000,00 | M250: =VLOOKUP(PAGOS_ACTUALIZAR_2026!B250,'CARGADOS 2025 DICIEMBRE CIERRE'!B250:B805,1,0) -> 2025003687
A251: 19/12/2025 | B251: 2025003688 | C251: 1125-2025 | D251: 3.150.000,00 | E251: 1082748783 | F251: JHONATTAN ALEXANDER CASTELLANOS ANDRADE | G251: 873 | J251: 873 | K251: 3.150.000,00 | M251: =VLOOKUP(PAGOS_ACTUALIZAR_2026!B251,'CARGADOS 2025 DICIEMBRE CIERRE'!B251:B806,1,0) -> 2025003688
A252: 19/12/2025 | B252: 2025003689 | C252: 780-2025 | D252: 7.800.000,00 | E252: 1022426162 | F252: KAREN MARGARITA LOPEZ BRAND | G252: 873 | J252: 873 | K252: 7.800.000,00 | M252: =VLOOKUP(PAGOS_ACTUALIZAR_2026!B252,'CARGADOS 2025 DICIEMBRE CIERRE'!B252:B807,1,0) -> 2025003689
... A321: 20/12/2025 | B321: 2025003762 | C321: 1187-2025 | D321: 3.150.000,00 | E321: 1086755989 | F321: MARIA FERNANDA NARVAEZ YEPEZ | G321: 873 | J321: 873 | K321: 3.150.000,00 | M321: =VLOOKUP(PAGOS_ACTUALIZAR_2026!B321,'CARGADOS 2025 DICIEMBRE CIERRE'!B321:B876,1,0) -> #N/A
A322: 20/12/2025 | B322: 2025003763 | C322: 1194-2025 | D322: 3.150.000,00 | E322: 1085246134 | F322: DIANA CAROLINA ROSERO CONCHA | G322: 873 | J322: 873 | K322: 3.150.000,00 | M322: =VLOOKUP(B322,'CARGADOS 2025 DICIEMBRE CIERRE'!B2:B557,1,0) -> 2025003763
A323: 20/12/2025 | B323: 2025003765 | C323: 768-2025 | D323: 4.730.000,00 | E323: 1085264667 | F323: DANNY ALEXANDER SANCHEZ ESTRADA | G323: 873 | J323: 873 | K323: 4.730.000,00 | M323: =VLOOKUP(B323,'CARGADOS 2025 DICIEMBRE CIERRE'!B3:B558,1,0) -> 2025003765
A324: 20/12/2025 | B324: 2025003767 | C324: 833-2025 | D324: 7.800.000,00 | E324: 1233189066 | F324: GERALDINE VIVIANA VILLOTA ARTEAGA | G324: 873 | J324: 873 | K324: 7.800.000,00 | M324: =VLOOKUP(B324,'CARGADOS 2025 DICIEMBRE CIERRE'!B4:B559,1,0) -> 2025003767
A325: 20/12/2025 | B325: 2025003771 | C325: 815-2025 | D325: 3.150.000,00 | E325: 1004131976 | F325: LUISA CAROLINA SANTACRUZ SANTACRUZ | G325: 873 | J325: 873 | K325: 3.150.000,00 | M325: =VLOOKUP(B325,'CARGADOS 2025 DICIEMBRE CIERRE'!B5:B560,1,0) -> 2025003771
A326: 20/12/2025 | B326: 2025003773 | C326: 872-2025 | D326: 3.150.000,00 | E326: 59122805 | F326: GLORIA JANETH BOTINA BURBANO | G326: 873 | J326: 873 | K326: 3.150.000,00 | M326: =VLOOKUP(B326,'CARGADOS 2025 DICIEMBRE CIERRE'!B6:B561,1,0) -> 2025003773
A327: 20/12/2025 | B327: 2025003776 | C327: 909-2025 | D327: 3.150.000,00 | E327: 1004709928 | F327: DEISY ANDREA MARTÍNEZ NARVAEZ | G327: 873 | J327: 873 | K327: 3.150.000,00 | M327: =VLOOKUP(B327,'CARGADOS 2025 DICIEMBRE CIERRE'!B7:B562,1,0) -> 2025003776
A328: 20/12/2025 | B328: 2025003780 | C328: 773-2025 | D328: 6.300.000,00 | E328: 1085286476 | F328: ELIANA STEPHANIE CAICEDO ALVAREZ | G328: 873 | J328: 873 | K328: 6.300.000,00 | M328: =VLOOKUP(B328,'CARGADOS 2025 DICIEMBRE CIERRE'!B8:B563,1,0) -> 2025003780
A329: 20/12/2025 | B329: 2025003781 | C329: 848-2025 | D329: 3.150.000,00 | E329: 1080690337 | F329: LUZ ANGELICA CHILES CABRERA | G329: 873 | J329: 873 | K329: 3.150.000,00 | M329: =VLOOKUP(B329,'CARGADOS 2025 DICIEMBRE CIERRE'!B9:B564,1,0) -> 2025003781
A330: 20/12/2025 | B330: 2025003782 | C330: 723-2025 | D330: 7.800.000,00 | E330: 1006946167 | F330: LIZETH MARCELA ORTÌZ MUÑOZ | G330: 873 | J330: 873 | K330: 7.800.000,00 | M330: =VLOOKUP(B330,'CARGADOS 2025 DICIEMBRE CIERRE'!B10:B565,1,0) -> 2025003782
A331: 20/12/2025 | B331: 2025003786 | C331: 1162-2025 | D331: 6.300.000,00 | E331: 1193223736 | F331: EMILY ROMERO MENDOZA | G331: 873 | J331: 873 | K331: 6.300.000,00 | M331: =VLOOKUP(B331,'CARGADOS 2025 DICIEMBRE CIERRE'!B11:B566,1,0) -> 2025003786
A332: 20/12/2025 | B332: 2025003788 | C332: 857-2025 | D332: 3.150.000,00 | E332: 1084224761 | F332: EDISON FAVER MARTINEZ LUNA | G332: 873 | J332: 873 | K332: 3.150.000,00 | M332: =VLOOKUP(B332,'CARGADOS 2025 DICIEMBRE CIERRE'!B12:B567,1,0) -> 2025003788
A333: 20/12/2025 | B333: 2025003789 | C333: 1005-2025 | D333: 2.000.000,00 | E333: 36933095 | F333: AURA VIRGINIA RIASCOS MORIANO | G333: 873 | J333: 873 | K333: 2.000.000,00 | M333: =VLOOKUP(B333,'CARGADOS 2025 DICIEMBRE CIERRE'!B13:B568,1,0) -> 2025003789
...

Sheet CARGADOS 2025 DICIEMBRE CIERRE
A1: fecha | B1: orden | C1: numero_contrato | D1: valor | E1: nit | F1: razon | G1: id_recurso | H1: indicador
A2: 46006 | B2: 2025003339 | C2: 953-2025 | D2: 4730000 | E2: 27105277 | F2: MARYBELL LUCIA BENITEZ ROSERO | G2: ID2087325712 | H2: I
A3: 46006 | B3: 2025003340 | C3: 877-2025 | D3: 3150000 | E3: 1085265947 | F3: MARCELA JAZMIN TIMANA MAIGUAL | G3: ID2087325712 | H3: I
A4: 46006 | B4: 2025003341 | C4: 982-2025 | D4: 3150000 | E4: 27222016 | F4: ALBA JULIA RODRIGUEZ MORA | G4: ID2087325712 | H4: I
A5: 46006 | B5: 2025003342 | C5: 1034-2025 | D5: 2000000 | E5: 59313273 | F5: AURA INES CHACHINOY POTOSI | G5: ID2087325712 | H5: I
A6: 46006 | B6: 2025003343 | C6: 1150-2025 | D6: 3150000 | E6: 1085331508 | F6: NESLY YANID MUÑOZ ORTÍZ | G6: ID2087325712 | H6: I
A7: 46006 | B7: 2025003344 | C7: 827-2025 | D7: 3150000 | E7: 27088197 | F7: PAULA ANDREA MANOSALVA UNIGARRO | G7: ID2087325712 | H7: I
A8: 46006 | B8: 2025003345 | C8: 951-2025 | D8: 6300000 | E8: 37085864 | F8: ANA VIVIANA BENAVIDES MORENO | G8: ID2087325712 | H8: I
A9: 46006 | B9: 2025003346 | C9: 1112-2025 | D9: 6300000 | E9: 1085254153 | F9: LISETH ELIANA BENAVIDES ARCOS | G9: ID2087325712 | H9: I
A10: 46006 | B10: 2025003347 | C10: 1165-2025 | D10: 3150000 | E10: 1233192104 | F10: DIEGO DAVID TORRES LUNA | G10: ID2087325712 | H10: I
A11: 46006 | B11: 2025003348 | C11: 1140-2025 | D11: 7800000 | E11: 1085307962 | F11: DANIELA ALEJANDRA TOBAR GOMEZ | G11: ID2087325712 | H11: I
A12: 46006 | B12: 2025003349 | C12: 860-2025 | D12: 4730000 | E12: 1005829176 | F12: ESTEFANIA CORREA GUERRERO | G12: ID2087325712 | H12: I
A13: 46006 | B13: 2025003350 | C13: 1040-2025 | D13: 7800000 | E13: 87065647 | F13: JHON JAIME LOPEZ GUERRERO | G13: ID2087325712 | H13: I
... A557: 46015 | B557: 2025004163 | C557: 952-2025 | D557: 3150000 | E557: 1081053820 | F557: ANDREA CATALINA CUASTUMAL ESCOBAR | G557: ID2087325712 | H557: I

Sheet PAGO_873
A1: fecha | B1: orden | C1: numero_contrato | D1: valor | E1: nit | F1: razon | G1: id_recurso | I1: indicador
A2: 45944 | B2: 2025002229 | C2: 790-2025 | D2: 3150000 | E2: 30743783 | F2: JAQUELINE MELO MOSQUERA | G2: ID2087325712 | H2: 790-2025 | I2: I
A3: 45944 | B3: 2025002236 | C3: 806-2025 | D3: 3150000 | E3: 1081053045 | F3: LUISA MARIA CERON RIVERA | G3: ID2087325712 | H3: 806-2025 | I3: I
A4: 45944 | B4: 2025002237 | C4: 887-2025 | D4: 1575000 | E4: 1085317226 | F4: MARIA ALEJANDRA BOLAÐOS ACOSTA | G4: ID2087325712 | H4: 887-2025 | I4: I
A5: 45944 | B5: 2025002242 | C5: 761-2025 | D5: 3150000 | E5: 1085269090 | F5: FHALOM CAROLINA ROSERO TORRES | G5: ID2087325712 | H5: 761-2025 | I5: I
A6: 45944 | B6: 2025002243 | C6: 829-2025 | D6: 3150000 | E6: 1086329609 | F6: LORENA DEL CARMEN OJEDA VAZQUEZ | G6: ID2087325712 | H6: 829-2025 | I6: I
A7: 45944 | B7: 2025002244 | C7: 904-2025 | D7: 3150000 | E7: 59837608 | F7: ALBA DENIS ARGOTY SANTACRUZ | G7: ID2087325712 | H7: 904-2025 | I7: I
A8: 45944 | B8: 2025002247 | C8: 714-2025 | D8: 4730000 | E8: 1193383306 | F8: MARIA DE LOS ANGELES ACOSTA ROSERO | G8: ID2087325712 | H8: 714-2025 | I8: I
A9: 45945 | B9: 2025002254 | C9: 696-2025 | D9: 151250000 | E9: 900994364 | F9: FUNDACIÓN CALIDAD DE VIDA Y ESPERANZA | G9: ID2087325712 | H9: 696-2025 | I9: I
A10: 45945 | B10: 2025002255 | C10: 862-2025 | D10: 6300000 | E10: 1085347312 | F10: SULEIDY YARITZA GOMEZ GARCIA | G10: ID2087325712 | H10: 862-2025 | I10: I
A11: 45945 | B11: 2025002256 | C11: 810-2025 | D11: 3150000 | E11: 37084285 | F11: JULIE ANDREA FREIRE MIER | G11: ID2087325712 | H11: 810-2025 | I11: I
A12: 45945 | B12: 2025002257 | C12: 872-2025 | D12: 3150000 | E12: 59122805 | F12: GLORIA JANETH BOTINA BURBANO | G12: ID2087325712 | H12: 872-2025 | I12: I
A13: 45945 | B13: 2025002258 | C13: 850-2025 | D13: 6300000 | E13: 97470681 | F13: FERNANDO TEOFILO ROSERO PATIÑO | G13: ID2087325712 | H13: 850-2025 | I13: I
... A169: 45961 | B169: 2025002535 | C169: 1076-2025 | D169: 72218841 | E169: 901329717 | F169: BIOPTICAS DE COLOMBIA SAS | G169: ID2087325712 | H169: 1076-2025 | I169: I
A170: 45965.401 | B170: 2025002555 | C170: 756-2025 | D170: 4730000 | E170: 1087414586 | F170: YULY MARCELA MORALES LOPEZ | G170: ID2087325712 | H170: 756-2025 | I170: I
A171: 45967.73 | B171: 2025002631 | C171: 739-2025 | D171: 3153000 | E171: 59312865 | F171: DIANA CAROLINA CORTES TAPIA | G171: ID2087325712 | H171: 739-2025 | I171: I
A172: 45972.429 | B172: 2025002677 | C172: 696-2025 | D172: 150342500 | E172: 900994364 | F172: FUNDACIÓN CALIDAD DE VIDA Y ESPERANZA | G172: ID2087325712 | H172: 696-2025 | I172: I
A173: 45973.394 | B173: 2025002687 | C173: 773-2025 | D173: 6300000 | E173: 1085286476 | F173: ELIANA STEPHANIE CAICEDO ALVAREZ | G173: ID2087325712 | H173: 773-2025 | I173: I
A174: 45973.398 | B174: 2025002688 | C174: 860-2025 | D174: 4730000 | E174: 1005829176 | F174: ESTEFANIA CORREA GUERRERO | G174: ID2087325712 | H174: 860-2025 | I174: I
A175: 45973.4 | B175: 2025002689 | C175: 754-2025 | D175: 3150000 | E175: 1233189234 | F175: YULLI KAROLINA CASTILLO PAZ | G175: ID2087325712 | H175: 754-2025 | I175: I
A176: 45973.403 | B176: 2025002690 | C176: 737-2025 | D176: 3150000 | E176: 1087006717 | F176: MIRYAM ELIZABETH POPAYAN PASCUAZA | G176: ID2087325712 | H176: 737-2025 | I176: I
A177: 45973.405 | B177: 2025002691 | C177: 777-2025 | D177: 3150000 | E177: 69028150 | F177: LYNN JANINA ORTIZ PAZ | G177: ID2087325712 | H177: 777-2025 | I177: I
A178: 45973.407 | B178: 2025002692 | C178: 732-2025 | D178: 3150000 | E178: 36752202 | F178: PAULA ANDREA ROCHA DELGADO | G178: ID2087325712 | H178: 732-2025 | I178: I
A179: 45974.41 | B179: 2025002699 | C179: 784-2025 | D179: 3150000 | E179: 1081272025 | F179: ANGIE GABRIELA ENRIQUEZ TACAN | G179: ID2087325712 | H179: 784-2025 | I179: I
A180: 45974.418 | B180: 2025002700 | C180: 798-2025 | D180: 3150000 | E180: 1085343154 | F180: BRIGIT VERONICA ORDOÑEZ BURBANO | G180: ID2087325712 | H180: 798-2025 | I180: I
A181: 45974.421 | B181: 2025002703 | C181: 883-2025 | D181: 3150000 | E181: 1004547484 | F181: YARY ESTEPHANIA BOLAÑOS LUNA | G181: ID2087325712 | H181: 883-2025 | I181: I
... A470: 46003.659 | B470: 2025003326 | C470: 1164-2025 | D470: 2000000 | E470: 1085287296 | F470: LILIANA LUCIA MAIGUAL MAIGUAL | G470: ID2087325712 | H470: 1164-2025 | I470: I
A471: 46006 | B471: 2025003339 | C471: 953-2025 | D471: 4730000 | E471: 27105277 | F471: MARYBELL LUCIA BENITEZ ROSERO | G471: ID2087325712 | H471: 953-2025 | I471: I
A472: 46006 | B472: 2025003340 | C472: 877-2025 | D472: 3150000 | E472: 1085265947 | F472: MARCELA JAZMIN TIMANA MAIGUAL | G472: ID2087325712 | H472: 877-2025 | I472: I
A473: 46006 | B473: 2025003341 | C473: 982-2025 | D473: 3150000 | E473: 27222016 | F473: ALBA JULIA RODRIGUEZ MORA | G473: ID2087325712 | H473: 982-2025 | I473: I
A474: 46006 | B474: 2025003342 | C474: 1034-2025 | D474: 2000000 | E474: 59313273 | F474: AURA INES CHACHINOY POTOSI | G474: ID2087325712 | H474: 1034-2025 | I474: I
A475: 46006 | B475: 2025003343 | C475: 1150-2025 | D475: 3150000 | E475: 1085331508 | F475: NESLY YANID MUÑOZ ORTÍZ | G475: ID2087325712 | H475: 1150-2025 | I475: I
A476: 46006 | B476: 2025003344 | C476: 827-2025 | D476: 3150000 | E476: 27088197 | F476: PAULA ANDREA MANOSALVA UNIGARRO | G476: ID2087325712 | H476: 827-2025 | I476: I
A477: 46006 | B477: 2025003345 | C477: 951-2025 | D477: 6300000 | E477: 37085864 | F477: ANA VIVIANA BENAVIDES MORENO | G477: ID2087325712 | H477: 951-2025 | I477: I
A478: 46006 | B478: 2025003346 | C478: 1112-2025 | D478: 6300000 | E478: 1085254153 | F478: LISETH ELIANA BENAVIDES ARCOS | G478: ID2087325712 | H478: 1112-2025 | I478: I
A479: 46006 | B479: 2025003347 | C479: 1165-2025 | D479: 3150000 | E479: 1233192104 | F479: DIEGO DAVID TORRES LUNA | G479: ID2087325712 | H479: 1165-2025 | I479: I
A480: 46006 | B480: 2025003348 | C480: 1140-2025 | D480: 7800000 | E480: 1085307962 | F480: DANIELA ALEJANDRA TOBAR GOMEZ | G480: ID2087325712 | H480: 1140-2025 | I480: I
A481: 46006 | B481: 2025003349 | C481: 860-2025 | D481: 4730000 | E481: 1005829176 | F481: ESTEFANIA CORREA GUERRERO | G481: ID2087325712 | H481: 860-2025 | I481: I
A482: 46006 | B482: 2025003350 | C482: 1040-2025 | D482: 7800000 | E482: 87065647 | F482: JHON JAIME LOPEZ GUERRERO | G482: ID2087325712 | H482: 1040-2025 | I482: I
... A1026: 46015 | B1026: 2025004163 | C1026: 952-2025 | D1026: 3150000 | E1026: 1081053820 | F1026: ANDREA CATALINA CUASTUMAL ESCOBAR | G1026: ID2087325712 | H1026: 952-2025 | I1026: I
...

Sheet PAGO_SUMATORIA
A1: contrato | B1: suma
A2: 790-2025 | B2: 12600000 | C2: =VLOOKUP(A2,'[1]ACTUALIZADO 2026'!$A$2:$A$338,1,0) -> 790-2025
A3: 806-2025 | B3: 12600000 | C3: =VLOOKUP(A3,'[1]ACTUALIZADO 2026'!$A$2:$A$338,1,0) -> 806-2025
A4: 887-2025 | B4: 11025000 | C4: =VLOOKUP(A4,'[1]ACTUALIZADO 2026'!$A$2:$A$338,1,0) -> 887-2025
A5: 761-2025 | B5: 12600000 | C5: =VLOOKUP(A5,'[1]ACTUALIZADO 2026'!$A$2:$A$338,1,0) -> 761-2025
A6: 829-2025 | B6: 12600000 | C6: =VLOOKUP(A6,'[1]ACTUALIZADO 2026'!$A$2:$A$338,1,0) -> 829-2025
A7: 904-2025 | B7: 22050000 | C7: =VLOOKUP(A7,'[1]ACTUALIZADO 2026'!$A$2:$A$338,1,0) -> 904-2025
A8: 714-2025 | B8: 18920000 | C8: =VLOOKUP(A8,'[1]ACTUALIZADO 2026'!$A$2:$A$338,1,0) -> 714-2025
A9: 696-2025 | B9: 603185000 | C9: =VLOOKUP(A9,'[1]ACTUALIZADO 2026'!$A$2:$A$338,1,0) -> 696-2025
A10: 862-2025 | B10: 25200000 | C10: =VLOOKUP(A10,'[1]ACTUALIZADO 2026'!$A$2:$A$338,1,0) -> 862-2025
A11: 810-2025 | B11: 12600000 | C11: =VLOOKUP(A11,'[1]ACTUALIZADO 2026'!$A$2:$A$338,1,0) -> 810-2025
A12: 872-2025 | B12: 12600000 | C12: =VLOOKUP(A12,'[1]ACTUALIZADO 2026'!$A$2:$A$338,1,0) -> 872-2025
A13: 850-2025 | B13: 25200000 | C13: =VLOOKUP(A13,'[1]ACTUALIZADO 2026'!$A$2:$A$338,1,0) -> 850-2025
... A325: 1187-2025 | B325: 9450000 | C325: =VLOOKUP(A325,'[1]ACTUALIZADO 2026'!$A$2:$A$338,1,0) -> 1187-2025
A326: 1256-2025 | B326: 2000000 | C326: =VLOOKUP(A326,'[1]ACTUALIZADO 2026'!$A$2:$A$338,1,0) -> #N/A | D326: N
